Workbook
Name OLE_LINK1: Pivot!$E$17
Name Slicer_Delivery_Status: #N/A
Name Slicer_Month: #N/A
Name Slicer_Payment_Method: #N/A
Name Slicer_Region: #N/A

Sheet Pivot
A2: 2. Show Total Sales Amount by Region and Product Category
A3: Region | B3: Product Category | C3: Sum of Sales Amount
A4: Central | B4: Books | C4: 84
B5: Electronics | C5: 2662 | E5: 2. Count of Orders by Delivery Status
B6: Fashion | C6: 210 | E6: Delivery Status | F6: Count of Order ID
B7: Home | C7: 2063 | E7: Cancelled | F7: 30
B8: Toys | C8: 437 | E8: Delivered | F8: 34
A9: Central Total | C9: 5456 | E9: In Transit | F9: 36
A10: East | B10: Books | C10: 394 | E10: Grand Total | F10: 100
B11: Electronics | C11: 365
B12: Fashion | C12: 711 | E12: 2. Average Delivery Time = Delivery Date – Order Date
B13: Home | C13: 741 | E13: Average of Time in delivery(Days)
B14: Toys | C14: 1424 | E14: 12.323529
A15: East Total | C15: 3635
A16: North | B16: Books | C16: 464
B17: Electronics | C17: 6522 | E17: 2. Add filter for Payment Method and Product Category
B18: Fashion | C18: 788 | E18: Product Category | F18: (All)
B19: Home | C19: 2131 | E19: Payment Method | F19: (All)
B20: Toys | C20: 586
A21: North Total | C21: 10491
A22: South | B22: Books | C22: 423
B23: Electronics | C23: 3938
B24: Fashion | C24: 1032
B25: Home | C25: 1881
B26: Toys | C26: 43
A27: South Total | C27: 7317
A28: West | B28: Books | C28: 350
B29: Electronics | C29: 1722
B30: Fashion | C30: 1131
B31: Home | C31: 4135
B32: Toys | C32: 1021
A33: West Total | C33: 8359
A34: Grand Total | C34: 35258
F36: KPI Cards
F38: 4. Total Revenue
A39: 4. Create a field: Cancellation Rate by Region (Cancelled Orders / Total Orders) | F39: Sum of Sales Amount
A40: Region | B40: Sum of Cancelled Flag | C40: Count of Order ID | F40: 35258
A41: Central | B41: 5 | C41: 14
A42: East | B42: 3 | C42: 18 | F42: 4. % of Fast Deliveries
A43: North | B43: 10 | C43: 25 | F43: Order status | G43: (All)
...

Sheet DashBoard

Sheet Insights
A2: Key Insights
A4: 1. Total Revenue: 35,258
A5: 2. Top Performing Region: North (10,491)
A6: 3. Highest Selling Product: Smartphone
A7: 4. Fast Deliveries: 77% of Orders
A8: 5. Top Regions: North & West
A9: 6. Interactive Filters: | C9: 1 | D9: Region
C10: 2 | D10: Delivery Status
C11: 3 | D11: Payment Method
C12: 4 | D12: Month

Sheet QA
A1: 1. What is the most successful product category in terms of revenue?
A2: >>Electronics is the most successful product category, generating the highest revenue compared to other categories
A4: 2. Which region has the highest order cancellation rate?
A5: >>The North region has the highest cancellation rate, indicating potential delivery or supply issues.
A7: 3. How many orders were delivered within 2 days?
A8: >>7 deliveres are delivered within 2 days.
A10: 4. How has the use of XLOOKUP simplified cross-sheet analysis?
A11: >>XLOOKUP simplified cross-sheet analysis by replacing complex VLOOKUP formulas.
A12: It allows dynamic lookups in any direction, eliminates column index errors, and provides built-in error handling,
A13: making data reconciliation faster and more reliable.
A15: 5. What recommendations would you give to improve delivery performance?
A16: >>Overall, the dashboard highlights key revenue drivers and delivery bottlenecks, enabling data-driven decisions to improve customer satisfaction and operational efficiency.

Sheet AmozonSales
A1: Order ID | B1: Order Date | C1: Month | D1: Year | E1: Delivery Date | F1: Cancel Date | G1: Customer ID | H1: Product ID | I1: Region | J1: Sale Price/Unit | K1: Quantity | L1: Total Amount | M1: Payment Method | N1: Delivery Status | O1: Fulfillment Partner | P1: Sales Amount | Q1: Time in delivery(Days) | R1: Product Category | S1: Customer Name | T1: Delivery Performance | U1: Date of Delivery | V1: Order status | W1: Cancelled Flag | X1: Product Name
A2: ORD0001 | B2: 45291 | C2: =TEXT(B2,"mmm") -> Dec | D2: =TEXT(B2,"yyy") -> 2023 | F2: 45323 | G2: CUST021 | H2: PROD012 | I2: North | J2: 44 | K2: 1 | L2: 44 | M2: Apple Pay | N2: Cancelled | O2: DHL | P2: =K2*J2 -> 44 | Q2: =IF(N2="Delivered",E2-B2,"") | R2: {=_xlfn.XLOOKUP(Table1[[#This Row],[Product ID]],Table2[[#All],[Product ID]],Table2[[#All],[Category]])} -> Home | S2: {=_xlfn.XLOOKUP(Table1[[#This Row],[Customer ID]],Table4[[#All],[Customer ID]],Table4[[#All],[Customer Name]])} -> Zoe Mitchell | T2: =IF(E2-B2<=2,"Fast","Slow") -> Fast | U2: =IFERROR(IF(E2="","Cancellations",E2),0) -> Cancellations | V2: =IF(OR(F2<>"",N2="Cancelled"),"Cancelled","Delivered") -> Cancelled | W2: =IF(V2="Cancelled",1,0) -> 1 | X2: =VLOOKUP(H2,ProductMaster!$A$1:$E$23,2,0) -> Lamp
A3: ORD0002 | B3: 44979 | C3: =TEXT(B3,"mmm") -> Feb | D3: =TEXT(B3,"yyy") -> 2023 | E3: 44981 | G3: CUST029 | H3: PROD018 | I3: East | J3: 96 | K3: 4 | L3: 384 | M3: Credit Card | N3: Delivered | O3: DHL | P3: =K3*J3 -> 384 | Q3: =IF(N3="Delivered",E3-B3,"") -> 2 | R3: {=_xlfn.XLOOKUP(Table1[[#This Row],[Product ID]],Table2[[#All],[Product ID]],Table2[[#All],[Category]])} -> Toys | S3: {=_xlfn.XLOOKUP(Table1[[#This Row],[Customer ID]],Table4[[#All],[Customer ID]],Table4[[#All],[Customer Name]])} -> Ava White | T3: =IF(E3-B3<=2,"Fast","Slow") -> Fast | U3: =IFERROR(IF(E3="","Cancellations",E3),0) -> 44981 | V3: =IF(OR(F3<>"",N3="Cancelled"),"Cancelled","Delivered") -> Delivered | W3: =IF(V3="Cancelled",1,0) -> 0 | X3: =VLOOKUP(H3,ProductMaster!$A$1:$E$23,2,0) -> Doll House
A4: ORD0003 | B4: 45240 | C4: =TEXT(B4,"mmm") -> Nov | D4: =TEXT(B4,"yyy") -> 2023 | G4: CUST021 | H4: PROD013 | I4: South | J4: 194 | K4: 4 | L4: 776 | M4: Credit Card | N4: In Transit | O4: USPS | P4: =K4*J4 -> 776 | Q4: =IF(N4="Delivered",E4-B4,"") | R4: {=_xlfn.XLOOKUP(Table1[[#This Row],[Product ID]],Table2[[#All],[Product ID]],Table2[[#All],[Category]])} -> Home | S4: {=_xlfn.XLOOKUP(Table1[[#This Row],[Customer ID]],Table4[[#All],[Customer ID]],Table4[[#All],[Customer Name]])} -> Zoe Mitchell | T4: =IF(E4-B4<=2,"Fast","Slow") -> Fast | U4: =IFERROR(IF(E4="","Cancellations",E4),0) -> Cancellations | V4: =IF(OR(F4<>"",N4="Cancelled"),"Cancelled","Delivered") -> Delivered | W4: =IF(V4="Cancelled",1,0) -> 0 | X4: =VLOOKUP(H4,ProductMaster!$A$1:$E$23,2,0) -> Vacuum Cleaner
A5: ORD0004 | B5: 45051 | C5: =TEXT(B5,"mmm") -> May | D5: =TEXT(B5,"yyy") -> 2023 | F5: 45235 | G5: CUST044 | H5: PROD013 | I5: North | J5: 196 | K5: 3 | L5: 588 | M5: PayPal | N5: Cancelled | O5: UPS | P5: =K5*J5 -> 588 | Q5: =IF(N5="Delivered",E5-B5,"") | R5: {=_xlfn.XLOOKUP(Table1[[#This Row],[Product ID]],Table2[[#All],[Product ID]],Table2[[#All],[Category]])} -> Home | S5: {=_xlfn.XLOOKUP(Table1[[#This Row],[Customer ID]],Table4[[#All],[Customer ID]],Table4[[#All],[Customer Name]])} -> Grace Ward | T5: =IF(E5-B5<=2,"Fast","Slow") -> Fast | U5: =IFERROR(IF(E5="","Cancellations",E5),0) -> Cancellations | V5: =IF(OR(F5<>"",N5="Cancelled"),"Cancelled","Delivered") -> Cancelled | W5: =IF(V5="Cancelled",1,0) -> 1 | X5: =VLOOKUP(H5,ProductMaster!$A$1:$E$23,2,0) -> Vacuum Cleaner
A6: ORD0005 | B6: 44959 | C6: =TEXT(B6,"mmm") -> Feb | D6: =TEXT(B6,"yyy") -> 2023 | E6: 45048 | G6: CUST027 | H6: PROD010 | I6: North | J6: 59 | K6: 1 | L6: 59 | M6: PayPal | N6: Delivered | O6: Amazon Logistics | P6: =K6*J6 -> 59 | Q6: =IF(N6="Delivered",E6-B6,"") -> 89 | R6: {=_xlfn.XLOOKUP(Table1[[#This Row],[Product ID]],Table2[[#All],[Product ID]],Table2[[#All],[Category]])} -> Fashion | S6: {=_xlfn.XLOOKUP(Table1[[#This Row],[Customer ID]],Table4[[#All],[Customer ID]],Table4[[#All],[Customer Name]])} -> Hazel Brooks | T6: =IF(E6-B6<=2,"Fast","Slow") -> Slow | U6: =IFERROR(IF(E6="","Cancellations",E6),0) -> 45048 | V6: =IF(OR(F6<>"",N6="Cancelled"),"Cancelled","Delivered") -> Delivered | W6: =IF(V6="Cancelled",1,0) -> 0 | X6: =VLOOKUP(H6,ProductMaster!$A$1:$E$23,2,0) -> Jeans
A7: ORD0006 | B7: 44937 | C7: =TEXT(B7,"mmm") -> Jan | D7: =TEXT(B7,"yyy") -> 2023 | F7: 44968 | G7: CUST009 | H7: PROD010 | I7: North | J7: 58 | K7: 4 | L7: 232 | M7: Amazon Pay | N7: Cancelled | O7: DHL | P7: =K7*J7 -> 232 | Q7: =IF(N7="Delivered",E7-B7,"") | R7: {=_xlfn.XLOOKUP(Table1[[#This Row],[Product ID]],Table2[[#All],[Product ID]],Table2[[#All],[Category]])} -> Fashion | S7: {=_xlfn.XLOOKUP(Table1[[#This Row],[Customer ID]],Table4[[#All],[Customer ID]],Table4[[#All],[Customer Name]])} -> Jackson Allen | T7: =IF(E7-B7<=2,"Fast","Slow") -> Fast | U7: =IFERROR(IF(E7="","Cancellations",E7),0) -> Cancellations | V7: =IF(OR(F7<>"",N7="Cancelled"),"Cancelled","Delivered") -> Cancelled | W7: =IF(V7="Cancelled",1,0) -> 1 | X7: =VLOOKUP(H7,ProductMaster!$A$1:$E$23,2,0) -> Jeans
A8: ORD0007 | B8: 45152 | C8: =TEXT(B8,"mmm") -> Aug | D8: =TEXT(B8,"yyy") -> 2023 | F8: 45156 | G8: CUST042 | H8: PROD020 | I8: Central | J8: 105 | K8: 3 | L8: 315 | M8: Debit Card | N8: Cancelled | O8: DHL | P8: =K8*J8 -> 315 | Q8: =IF(N8="Delivered",E8-B8,"") | R8: {=_xlfn.XLOOKUP(Table1[[#This Row],[Product ID]],Table2[[#All],[Product ID]],Table2[[#All],[Category]])} -> Electronics | S8: {=_xlfn.XLOOKUP(Table1[[#This Row],[Customer ID]],Table4[[#All],[Customer ID]],Table4[[#All],[Customer Name]])} -> Noah Wilson | T8: =IF(E8-B8<=2,"Fast","Slow") -> Fast | U8: =IFERROR(IF(E8="","Cancellations",E8),0) -> Cancellations | V8: =IF(OR(F8<>"",N8="Cancelled"),"Cancelled","Delivered") -> Cancelled | W8: =IF(V8="Cancelled",1,0) -> 1 | X8: =VLOOKUP(H8,ProductMaster!$A$1:$E$23,2,0) -> Bluetooth Speaker
A9: ORD0008 | B9: 44930 | C9: =TEXT(B9,"mmm") -> Jan | D9: =TEXT(B9,"yyy") -> 2023 | F9: 45081 | G9: CUST019 | H9: PROD021 | I9: West | J9: 37 | K9: 5 | L9: 185 | M9: PayPal | N9: Cancelled | O9: DHL | P9: =K9*J9 -> 185 | Q9: =IF(N9="Delivered",E9-B9,"") | R9: {=_xlfn.XLOOKUP(Table1[[#This Row],[Product ID]],Table2[[#All],[Product ID]],Table2[[#All],[Category]])} -> Home | S9: {=_xlfn.XLOOKUP(Table1[[#This Row],[Customer ID]],Table4[[#All],[Customer ID]],Table4[[#All],[Customer Name]])} -> Ava Robinson | T9: =IF(E9-B9<=2,"Fast","Slow") -> Fast | U9: =IFERROR(IF(E9="","Cancellations",E9),0) -> Cancellations | V9: =IF(OR(F9<>"",N9="Cancelled"),"Cancelled","Delivered") -> Cancelled | W9: =IF(V9="Cancelled",1,0) -> 1 | X9: =VLOOKUP(H9,ProductMaster!$A$1:$E$23,2,0) -> Wall Clock
A10: ORD0009 | B10: 45128 | C10: =TEXT(B10,"mmm") -> Jul | D10: =TEXT(B10,"yyy") -> 2023 | G10: CUST013 | H10: PROD019 | I10: Central | J10: 44 | K10: 2 | L10: 88 | M10: Credit Card | N10: In Transit | O10: Amazon Logistics | P10: =K10*J10 -> 88 | Q10: =IF(N10="Delivered",E10-B10,"") | R10: {=_xlfn.XLOOKUP(Table1[[#This Row],[Product ID]],Table2[[#All],[Product ID]],Table2[[#All],[Category]])} -> Fashion | S10: {=_xlfn.XLOOKUP(Table1[[#This Row],[Customer ID]],Table4[[#All],[Customer ID]],Table4[[#All],[Customer Name]])} -> Olivia Martinez | T10: =IF(E10-B10<=2,"Fast","Slow") -> Fast | U10: =IFERROR(IF(E10="","Cancellations",E10),0) -> Cancellations | V10: =IF(OR(F10<>"",N10="Cancelled"),"Cancelled","Delivered") -> Delivered | W10: =IF(V10="Cancelled",1,0) -> 0 | X10: =VLOOKUP(H10,ProductMaster!$A$1:$E$23,2,0) -> Formal Shirt
A11: ORD0010 | B11: 45289 | C11: =TEXT(B11,"mmm") -> Dec | D11: =TEXT(B11,"yyy") -> 2023 | G11: CUST019 | H11: PROD003 | I11: South | J11: 141 | K11: 4 | L11: 564 | M11: Debit Card | N11: In Transit | O11: DHL | P11: =K11*J11 -> 564 | Q11: =IF(N11="Delivered",E11-B11,"") | R11: {=_xlfn.XLOOKUP(Table1[[#This Row],[Product ID]],Table2[[#All],[Product ID]],Table2[[#All],[Category]])} -> Home | S11: {=_xlfn.XLOOKUP(Table1[[#This Row],[Customer ID]],Table4[[#All],[Customer ID]],Table4[[#All],[Customer Name]])} -> Ava Robinson | T11: =IF(E11-B11<=2,"Fast","Slow") -> Fast | U11: =IFERROR(IF(E11="","Cancellations",E11),0) -> Cancellations | V11: =IF(OR(F11<>"",N11="Cancelled"),"Cancelled","Delivered") -> Delivered | W11: =IF(V11="Cancelled",1,0) -> 0 | X11: =VLOOKUP(H11,ProductMaster!$A$1:$E$23,2,0) -> Cookware Set
A12: ORD0011 | B12: 45021 | C12: =TEXT(B12,"mmm") -> Apr | D12: =TEXT(B12,"yyy") -> 2023 | F12: 45143 | G12: CUST046 | H12: PROD014 | I12: South | J12: 249 | K12: 1 | L12: 249 | M12: Amazon Pay | N12: Cancelled | O12: USPS | P12: =K12*J12 -> 249 | Q12: =IF(N12="Delivered",E12-B12,"") | R12: {=_xlfn.XLOOKUP(Table1[[#This Row],[Product ID]],Table2[[#All],[Product ID]],Table2[[#All],[Category]])} -> Electronics | S12: {=_xlfn.XLOOKUP(Table1[[#This Row],[Customer ID]],Table4[[#All],[Customer ID]],Table4[[#All],[Customer Name]])} -> Emily Johnson | T12: =IF(E12-B12<=2,"Fast","Slow") -> Fast | U12: =IFERROR(IF(E12="","Cancellations",E12),0) -> Cancellations | V12: =IF(OR(F12<>"",N12="Cancelled"),"Cancelled","Delivered") -> Cancelled | W12: =IF(V12="Cancelled",1,0) -> 1 | X12: =VLOOKUP(H12,ProductMaster!$A$1:$E$23,2,0) -> Smartwatch
A13: ORD0012 | B13: 45132 | C13: =TEXT(B13,"mmm") -> Jul | D13: =TEXT(B13,"yyy") -> 2023 | G13: CUST045 | H13: PROD014 | I13: Central | J13: 247 | K13: 3 | L13: 741 | M13: Amazon Pay | N13: In Transit | O13: FedEx | P13: =K13*J13 -> 741 | Q13: =IF(N13="Delivered",E13-B13,"") | R13: {=_xlfn.XLOOKUP(Table1[[#This Row],[Product ID]],Table2[[#All],[Product ID]],Table2[[#All],[Category]])} -> Electronics | S13: {=_xlfn.XLOOKUP(Table1[[#This Row],[Customer ID]],Table4[[#All],[Customer ID]],Table4[[#All],[Customer Name]])} -> Emily Johnson | T13: =IF(E13-B13<=2,"Fast","Slow") -> Fast | U13: =IFERROR(IF(E13="","Cancellations",E13),0) -> Cancellations | V13: =IF(OR(F13<>"",N13="Cancelled"),"Cancelled","Delivered") -> Delivered | W13: =IF(V13="Cancelled",1,0) -> 0 | X13: =VLOOKUP(H13,ProductMaster!$A$1:$E$23,2,0) -> Smartwatch
A14: ORD0013 | B14: 44982 | C14: =TEXT(B14,"mmm") -> Feb | D14: =TEXT(B14,"yyy") -> 2023 | F14: 44985 | G14: CUST023 | H14: PROD006 | I14: Central | J14: 96 | K14: 1 | L14: 96 | M14: Apple Pay | N14: Cancelled | O14: Amazon Logistics | P14: =K14*J14 -> 96 | Q14: =IF(N14="Delivered",E14-B14,"") | R14: {=_xlfn.XLOOKUP(Table1[[#This Row],[Product ID]],Table2[[#All],[Product ID]],Table2[[#All],[Category]])} -> Fashion | S14: {=_xlfn.XLOOKUP(Table1[[#This Row],[Customer ID]],Table4[[#All],[Customer ID]],Table4[[#All],[Customer Name]])} -> Charlotte Reed | T14: =IF(E14-B14<=2,"Fast","Slow") -> Fast | U14: =IFERROR(IF(E14="","Cancellations",E14),0) -> Cancellations | V14: =IF(OR(F14<>"",N14="Cancelled"),"Cancelled","Delivered") -> Cancelled | W14: =IF(V14="Cancelled",1,0) -> 1 | X14: =VLOOKUP(H14,ProductMaster!$A$1:$E$23,2,0) -> Shoes
A15: ORD0014 | B15: 44981 | C15: =TEXT(B15,"mmm") -> Feb | D15: =TEXT(B15,"yyy") -> 2023 | F15: 44982 | G15: CUST033 | H15: PROD017 | I15: West | J15: 74 | K15: 5 | L15: 370 | M15: Apple Pay | N15: Cancelled | O15: Amazon Logistics | P15: =K15*J15 -> 370 | Q15: =IF(N15="Delivered",E15-B15,"") | R15: {=_xlfn.XLOOKUP(Table1[[#This Row],[Product ID]],Table2[[#All],[Product ID]],Table2[[#All],[Category]])} -> Electronics | S15: {=_xlfn.XLOOKUP(Table1[[#This Row],[Customer ID]],Table4[[#All],[Customer ID]],Table4[[#All],[Customer Name]])} -> Hazel Rivera | T15: =IF(E15-B15<=2,"Fast","Slow") -> Fast | U15: =IFERROR(IF(E15="","Cancellations",E15),0) -> Cancellations | V15: =IF(OR(F15<>"",N15="Cancelled"),"Cancelled","Delivered") -> Cancelled | W15: =IF(V15="Cancelled",1,0) -> 1 | X15: =VLOOKUP(H15,ProductMaster!$A$1:$E$23,2,0) -> Gaming Mouse
A16: ORD0015 | B16: 45164 | C16: =TEXT(B16,"mmm") -> Aug | D16: =TEXT(B16,"yyy") -> 2023 | F16: 44966 | G16: CUST033 | H16: PROD005 | I16: South | J16: 27 | K16: 1 | L16: 27 | M16: Credit Card | N16: Cancelled | O16: Amazon Logistics | P16: =K16*J16 -> 27 | Q16: =IF(N16="Delivered",E16-B16,"") | R16: {=_xlfn.XLOOKUP(Table1[[#This Row],[Product ID]],Table2[[#All],[Product ID]],Table2[[#All],[Category]])} -> Fashion | S16: {=_xlfn.XLOOKUP(Table1[[#This Row],[Customer ID]],Table4[[#All],[Customer ID]],Table4[[#All],[Customer Name]])} -> Hazel Rivera | T16: =IF(E16-B16<=2,"Fast","Slow") -> Fast | U16: =IFERROR(IF(E16="","Cancellations",E16),0) -> Cancellations | V16: =IF(OR(F16<>"",N16="Cancelled"),"Cancelled","Delivered") -> Cancelled | W16: =IF(V16="Cancelled",1,0) -> 1 | X16: =VLOOKUP(H16,ProductMaster!$A$1:$E$23,2,0) -> T-Shirt
A17: ORD0016 | B17: 44970 | C17: =TEXT(B17,"mmm") -> Feb | D17: =TEXT(B17,"yyy") -> 2023 | G17: CUST047 | H17: PROD005 | I17: South | J17: 27 | K17: 3 | L17: 81 | M17: Debit Card | N17: In Transit | O17: Amazon Logistics | P17: =K17*J17 -> 81 | Q17: =IF(N17="Delivered",E17-B17,"") | R17: {=_xlfn.XLOOKUP(Table1[[#This Row],[Product ID]],Table2[[#All],[Product ID]],Table2[[#All],[Category]])} -> Fashion | S17: {=_xlfn.XLOOKUP(Table1[[#This Row],[Customer ID]],Table4[[#All],[Customer ID]],Table4[[#All],[Customer Name]])} -> Scarlett Murphy | T17: =IF(E17-B17<=2,"Fast","Slow") -> Fast | U17: =IFERROR(IF(E17="","Cancellations",E17),0) -> Cancellations | V17: =IF(OR(F17<>"",N17="Cancelled"),"Cancelled","Delivered") -> Delivered | W17: =IF(V17="Cancelled",1,0) -> 0 | X17: =VLOOKUP(H17,ProductMaster!$A$1:$E$23,2,0) -> T-Shirt
A18: ORD0017 | B18: 45105 | C18: =TEXT(B18,"mmm") -> Jun | D18: =TEXT(B18,"yyy") -> 2023 | E18: 44933 | G18: CUST045 | H18: PROD015 | I18: East | J18: 21 | K18: 3 | L18: 63 | M18: Credit Card | N18: Delivered | O18: DHL | P18: =K18*J18 -> 63 | Q18: =IF(N18="Delivered",E18-B18,"") -> -172 | R18: {=_xlfn.XLOOKUP(Table1[[#This Row],[Product ID]],Table2[[#All],[Product ID]],Table2[[#All],[Category]])} -> Books | S18: {=_xlfn.XLOOKUP(Table1[[#This Row],[Customer ID]],Table4[[#All],[Customer ID]],Table4[[#All],[Customer Name]])} -> Emily Johnson | T18: =IF(E18-B18<=2,"Fast","Slow") -> Fast | U18: =IFERROR(IF(E18="","Cancellations",E18),0) -> 44933 | V18: =IF(OR(F18<>"",N18="Cancelled"),"Cancelled","Delivered") -> Delivered | W18: =IF(V18="Cancelled",1,0) -> 0 | X18: =VLOOKUP(H18,ProductMaster!$A$1:$E$23,2,0) -> Novel
A19: ORD0018 | B19: 45258 | C19: =TEXT(B19,"mmm") -> Nov | D19: =TEXT(B19,"yyy") -> 2023 | G19: CUST011 | H19: PROD008 | I19: West | J19: 70 | K19: 5 | L19: 350 | M19: PayPal | N19: In Transit | O19: Amazon Logistics | P19: =K19*J19 -> 350 | Q19: =IF(N19="Delivered",E19-B19,"") | R19: {=_xlfn.XLOOKUP(Table1[[#This Row],[Product ID]],Table2[[#All],[Product ID]],Table2[[#All],[Category]])} -> Books | S19: {=_xlfn.XLOOKUP(Table1[[#This Row],[Customer ID]],Table4[[#All],[Customer ID]],Table4[[#All],[Customer Name]])} -> Mason Hall | T19: =IF(E19-B19<=2,"Fast","Slow") -> Fast | U19: =IFERROR(IF(E19="","Cancellations",E19),0) -> Cancellations | V19: =IF(OR(F19<>"",N19="Cancelled"),"Cancelled","Delivered") -> Delivered | W19: =IF(V19="Cancelled",1,0) -> 0 | X19: =VLOOKUP(H19,ProductMaster!$A$1:$E$23,2,0) -> Textbook
A20: ORD0019 | B20: 45163 | C20: =TEXT(B20,"mmm") -> Aug | D20: =TEXT(B20,"yyy") -> 2023 | G20: CUST041 | H20: PROD006 | I20: South | J20: 94 | K20: 4 | L20: 376 | M20: Credit Card | N20: In Transit | O20: USPS | P20: =K20*J20 -> 376 | Q20: =IF(N20="Delivered",E20-B20,"") | R20: {=_xlfn.XLOOKUP(Table1[[#This Row],[Product ID]],Table2[[#All],[Product ID]],Table2[[#All],[Category]])} -> Fashion | S20: {=_xlfn.XLOOKUP(Table1[[#This Row],[Customer ID]],Table4[[#All],[Customer ID]],Table4[[#All],[Customer Name]])} -> Jacob Price | T20: =IF(E20-B20<=2,"Fast","Slow") -> Fast | U20: =IFERROR(IF(E20="","Cancellations",E20),0) -> Cancellations | V20: =IF(OR(F20<>"",N20="Cancelled"),"Cancelled","Delivered") -> Delivered | W20: =IF(V20="Cancelled",1,0) -> 0 | X20: =VLOOKUP(H20,ProductMaster!$A$1:$E$23,2,0) -> Shoes
A21: ORD0020 | B21: 45264 | C21: =TEXT(B21,"mmm") -> Dec | D21: =TEXT(B21,"yyy") -> 2023 | G21: CUST025 | H21: PROD001 | I21: North | J21: 813 | K21: 2 | L21: 1626 | M21: Credit Card | N21: In Transit | O21: FedEx | P21: =K21*J21 -> 1626 | Q21: =IF(N21="Delivered",E21-B21,"") | R21: {=_xlfn.XLOOKUP(Table1[[#This Row],[Product ID]],Table2[[#All],[Product ID]],Table2[[#All],[Category]])} -> Electronics | S21: {=_xlfn.XLOOKUP(Table1[[#This Row],[Customer ID]],Table4[[#All],[Customer ID]],Table4[[#All],[Customer Name]])} -> Emma King | T21: =IF(E21-B21<=2,"Fast","Slow") -> Fast | U21: =IFERROR(IF(E21="","Cancellations",E21),0) -> Cancellations | V21: =IF(OR(F21<>"",N21="Cancelled"),"Cancelled","Delivered") -> Delivered | W21: =IF(V21="Cancelled",1,0) -> 0 | X21: =VLOOKUP(H21,ProductMaster!$A$1:$E$23,2,0) -> Smartphone
A22: ORD0021 | B22: 44967 | C22: =TEXT(B22,"mmm") -> Feb | D22: =TEXT(B22,"yyy") -> 2023 | G22: CUST013 | H22: PROD015 | I22: Central | J22: 21 | K22: 4 | L22: 84 | M22: PayPal | N22: In Transit | O22: Amazon Logistics | P22: =K22*J22 -> 84 | Q22: =IF(N22="Delivered",E22-B22,"") | R22: {=_xlfn.XLOOKUP(Table1[[#This Row],[Product ID]],Table2[[#All],[Product ID]],Table2[[#All],[Category]])} -> Books | S22: {=_xlfn.XLOOKUP(Table1[[#This Row],[Customer ID]],Table4[[#All],[Customer ID]],Table4[[#All],[Customer Name]])} -> Olivia Martinez | T22: =IF(E22-B22<=2,"Fast","Slow") -> Fast | U22: =IFERROR(IF(E22="","Cancellations",E22),0) -> Cancellations | V22: =IF(OR(F22<>"",N22="Cancelled"),"Cancelled","Delivered") -> Delivered | W22: =IF(V22="Cancelled",1,0) -> 0 | X22: =VLOOKUP(H22,ProductMaster!$A$1:$E$23,2,0) -> Novel
A23: ORD0022 | B23: 45180 | C23: =TEXT(B23,"mmm") -> Sep | D23: =TEXT(B23,"yyy") -> 2023 | G23: CUST023 | H23: PROD012 | I23: West | J23: 46 | K23: 5 | L23: 230 | M23: PayPal | N23: In Transit | O23: USPS | P23: =K23*J23 -> 230 | Q23: =IF(N23="Delivered",E23-B23,"") | R23: {=_xlfn.XLOOKUP(Table1[[#This Row],[Product ID]],Table2[[#All],[Product ID]],Table2[[#All],[Category]])} -> Home | S23: {=_xlfn.XLOOKUP(Table1[[#This Row],[Customer ID]],Table4[[#All],[Customer ID]],Table4[[#All],[Customer Name]])} -> Charlotte Reed | T23: =IF(E23-B23<=2,"Fast","Slow") -> Fast | U23: =IFERROR(IF(E23="","Cancellations",E23),0) -> Cancellations | V23: =IF(OR(F23<>"",N23="Cancelled"),"Cancelled","Delivered") -> Delivered | W23: =IF(V23="Cancelled",1,0) -> 0 | X23: =VLOOKUP(H23,ProductMaster!$A$1:$E$23,2,0) -> Lamp
A24: ORD0023 | B24: 44970 | C24: =TEXT(B24,"mmm") -> Feb | D24: =TEXT(B24,"yyy") -> 2023 | F24: 44971 | G24: CUST016 | H24: PROD010 | I24: West | J24: 58 | K24: 3 | L24: 174 | M24: Amazon Pay | N24: Cancelled | O24: Amazon Logistics | P24: =K24*J24 -> 174 | Q24: =IF(N24="Delivered",E24-B24,"") | R24: {=_xlfn.XLOOKUP(Table1[[#This Row],[Product ID]],Table2[[#All],[Product ID]],Table2[[#All],[Category]])} -> Fashion | S24: {=_xlfn.XLOOKUP(Table1[[#This Row],[Customer ID]],Table4[[#All],[Customer ID]],Table4[[#All],[Customer Name]])} -> Elijah Lewis | T24: =IF(E24-B24<=2,"Fast","Slow") -> Fast | U24: =IFERROR(IF(E24="","Cancellations",E24),0) -> Cancellations | V24: =IF(OR(F24<>"",N24="Cancelled"),"Cancelled","Delivered") -> Cancelled | W24: =IF(V24="Cancelled",1,0) -> 1 | X24: =VLOOKUP(H24,ProductMaster!$A$1:$E$23,2,0) -> Jeans
A25: ORD0024 | B25: 44968 | C25: =TEXT(B25,"mmm") -> Feb | D25: =TEXT(B25,"yyy") -> 2023 | E25: 45057 | G25: CUST028 | H25: PROD006 | I25: West | J25: 96 | K25: 5 | L25: 480 | M25: Amazon Pay | N25: Delivered | O25: Amazon Logistics | P25: =K25*J25 -> 480 | Q25: =IF(N25="Delivered",E25-B25,"") -> 89 | R25: {=_xlfn.XLOOKUP(Table1[[#This Row],[Product ID]],Table2[[#All],[Product ID]],Table2[[#All],[Category]])} -> Fashion | S25: {=_xlfn.XLOOKUP(Table1[[#This Row],[Customer ID]],Table4[[#All],[Customer ID]],Table4[[#All],[Customer Name]])} -> Lily Bennett | T25: =IF(E25-B25<=2,"Fast","Slow") -> Slow | U25: =IFERROR(IF(E25="","Cancellations",E25),0) -> 45057 | V25: =IF(OR(F25<>"",N25="Cancelled"),"Cancelled","Delivered") -> Delivered | W25: =IF(V25="Cancelled",1,0) -> 0 | X25: =VLOOKUP(H25,ProductMaster!$A$1:$E$23,2,0) -> Shoes
A26: ORD0025 | B26: 45074 | C26: =TEXT(B26,"mmm") -> May | D26: =TEXT(B26,"yyy") -> 2023 | E26: 45076 | G26: CUST040 | H26: PROD002 | I26: South | J26: 43 | K26: 1 | L26: 43 | M26: Debit Card | N26: Delivered | O26: Amazon Logistics | P26: =K26*J26 -> 43 | Q26: =IF(N26="Delivered",E26-B26,"") -> 2 | R26: {=_xlfn.XLOOKUP(Table1[[#This Row],[Product ID]],Table2[[#All],[Product ID]],Table2[[#All],[Category]])} -> Toys | S26: {=_xlfn.XLOOKUP(Table1[[#This Row],[Customer ID]],Table4[[#All],[Customer ID]],Table4[[#All],[Customer Name]])} -> Benjamin Clark | T26: =IF(E26-B26<=2,"Fast","Slow") -> Fast | U26: =IFERROR(IF(E26="","Cancellations",E26),0) -> 45076 | V26: =IF(OR(F26<>"",N26="Cancelled"),"Cancelled","Delivered") -> Delivered | W26: =IF(V26="Cancelled",1,0) -> 0 | X26: =VLOOKUP(H26,ProductMaster!$A$1:$E$23,2,0) -> Action Figure
A27: ORD0026 | B27: 45214 | C27: =TEXT(B27,"mmm") -> Oct | D27: =TEXT(B27,"yyy") -> 2023 | E27: 45220 | G27: CUST027 | H27: PROD022 | I27: South | J27: 64 | K27: 4 | L27: 256 | M27: Debit Card | N27: Delivered | O27: USPS | P27: =K27*J27 -> 256 | Q27: =IF(N27="Delivered",E27-B27,"") -> 6 | R27: {=_xlfn.XLOOKUP(Table1[[#This Row],[Product ID]],Table2[[#All],[Product ID]],Table2[[#All],[Category]])} -> Fashion | S27: {=_xlfn.XLOOKUP(Table1[[#This Row],[Customer ID]],Table4[[#All],[Customer ID]],Table4[[#All],[Customer Name]])} -> Hazel Brooks | T27: =IF(E27-B27<=2,"Fast","Slow") -> Slow | U27: =IFERROR(IF(E27="","Cancellations",E27),0) -> 45220 | V27: =IF(OR(F27<>"",N27="Cancelled"),"Cancelled","Delivered") -> Delivered | W27: =IF(V27="Cancelled",1,0) -> 0 | X27: =VLOOKUP(H27,ProductMaster!$A$1:$E$23,2,0) -> Backpack
A28: ORD0027 | B28: 44942 | C28: =TEXT(B28,"mmm") -> Jan | D28: =TEXT(B28,"yyy") -> 2023 | G28: CUST018 | H28: PROD008 | I28: South | J28: 70 | K28: 2 | L28: 140 | M28: Amazon Pay | N28: In Transit | O28: Amazon Logistics | P28: =K28*J28 -> 140 | Q28: =IF(N28="Delivered",E28-B28,"") | R28: {=_xlfn.XLOOKUP(Table1[[#This Row],[Product ID]],Table2[[#All],[Product ID]],Table2[[#All],[Category]])} -> Books | S28: {=_xlfn.XLOOKUP(Table1[[#This Row],[Customer ID]],Table4[[#All],[Customer ID]],Table4[[#All],[Customer Name]])} -> Grace Scott | T28: =IF(E28-B28<=2,"Fast","Slow") -> Fast | U28: =IFERROR(IF(E28="","Cancellations",E28),0) -> Cancellations | V28: =IF(OR(F28<>"",N28="Cancelled"),"Cancelled","Delivered") -> Delivered | W28: =IF(V28="Cancelled",1,0) -> 0 | X28: =VLOOKUP(H28,ProductMaster!$A$1:$E$23,2,0) -> Textbook
A29: ORD0028 | B29: 45179 | C29: =TEXT(B29,"mmm") -> Sep | D29: =TEXT(B29,"yyy") -> 2023 | G29: CUST018 | H29: PROD018 | I29: Central | J29: 97 | K29: 3 | L29: 291 | M29: Credit Card | N29: In Transit | O29: Amazon Logistics | P29: =K29*J29 -> 291 | Q29: =IF(N29="Delivered",E29-B29,"") | R29: {=_xlfn.XLOOKUP(Table1[[#This Row],[Product ID]],Table2[[#All],[Product ID]],Table2[[#All],[Category]])} -> Toys | S29: {=_xlfn.XLOOKUP(Table1[[#This Row],[Customer ID]],Table4[[#All],[Customer ID]],Table4[[#All],[Customer Name]])} -> Grace Scott | T29: =IF(E29-B29<=2,"Fast","Slow") -> Fast | U29: =IFERROR(IF(E29="","Cancellations",E29),0) -> Cancellations | V29: =IF(OR(F29<>"",N29="Cancelled"),"Cancelled","Delivered") -> Delivered | W29: =IF(V29="Cancelled",1,0) -> 0 | X29: =VLOOKUP(H29,ProductMaster!$A$1:$E$23,2,0) -> Doll House
A30: ORD0029 | B30: 45117 | C30: =TEXT(B30,"mmm") -> Jul | D30: =TEXT(B30,"yyy") -> 2023 | F30: 45209 | G30: CUST007 | H30: PROD021 | I30: East | J30: 37 | K30: 3 | L30: 111 | M30: Apple Pay | N30: Cancelled | O30: DHL | P30: =K30*J30 -> 111 | Q30: =IF(N30="Delivered",E30-B30,"") | R30: {=_xlfn.XLOOKUP(Table1[[#This Row],[Product ID]],Table2[[#All],[Product ID]],Table2[[#All],[Category]])} -> Home | S30: {=_xlfn.XLOOKUP(Table1[[#This Row],[Customer ID]],Table4[[#All],[Customer ID]],Table4[[#All],[Customer Name]])} -> Liam Walker | T30: =IF(E30-B30<=2,"Fast","Slow") -> Fast | U30: =IFERROR(IF(E30="","Cancellations",E30),0) -> Cancellations | V30: =IF(OR(F30<>"",N30="Cancelled"),"Cancelled","Delivered") -> Cancelled | W30: =IF(V30="Cancelled",1,0) -> 1 | X30: =VLOOKUP(H30,ProductMaster!$A$1:$E$23,2,0) -> Wall Clock
A31: ORD0030 | B31: 44971 | C31: =TEXT(B31,"mmm") -> Feb | D31: =TEXT(B31,"yyy") -> 2023 | G31: CUST008 | H31: PROD008 | I31: North | J31: 69 | K31: 5 | L31: 345 | M31: Amazon Pay | N31: In Transit | O31: Amazon Logistics | P31: =K31*J31 -> 345 | Q31: =IF(N31="Delivered",E31-B31,"") | R31: {=_xlfn.XLOOKUP(Table1[[#This Row],[Product ID]],Table2[[#All],[Product ID]],Table2[[#All],[Category]])} -> Books | S31: {=_xlfn.XLOOKUP(Table1[[#This Row],[Customer ID]],Table4[[#All],[Customer ID]],Table4[[#All],[Customer Name]])} -> Harper Young | T31: =IF(E31-B31<=2,"Fast","Slow") -> Fast | U31: =IFERROR(IF(E31="","Cancellations",E31),0) -> Cancellations | V31: =IF(OR(F31<>"",N31="Cancelled"),"Cancelled","Delivered") -> Delivered | W31: =IF(V31="Cancelled",1,0) -> 0 | X31: =VLOOKUP(H31,ProductMaster!$A$1:$E$23,2,0) -> Textbook
A32: ORD0031 | B32: 45011 | C32: =TEXT(B32,"mmm") -> Mar | D32: =TEXT(B32,"yyy") -> 2023 | G32: CUST014 | H32: PROD002 | I32: North | J32: 42 | K32: 5 | L32: 210 | M32: Amazon Pay | N32: In Transit | O32: UPS | P32: =K32*J32 -> 210 | Q32: =IF(N32="Delivered",E32-B32,"") | R32: {=_xlfn.XLOOKUP(Table1[[#This Row],[Product ID]],Table2[[#All],[Product ID]],Table2[[#All],[Category]])} -> Toys | S32: {=_xlfn.XLOOKUP(Table1[[#This Row],[Customer ID]],Table4[[#All],[Customer ID]],Table4[[#All],[Customer Name]])} -> Harper Young | T32: =IF(E32-B32<=2,"Fast","Slow") -> Fast | U32: =IFERROR(IF(E32="","Cancellations",E32),0) -> Cancellations | V32: =IF(OR(F32<>"",N32="Cancelled"),"Cancelled","Delivered") -> Delivered | W32: =IF(V32="Cancelled",1,0) -> 0 | X32: =VLOOKUP(H32,ProductMaster!$A$1:$E$23,2,0) -> Action Figure
A33: ORD0032 | B33: 45092 | C33: =TEXT(B33,"mmm") -> Jun | D33: =TEXT(B33,"yyy") -> 2023 | F33: 45099 | G33: CUST037 | H33: PROD009 | I33: East | J33: 11 | K33: 5 | L33: 55 | M33: Debit Card | N33: Cancelled | O33: FedEx | P33: =K33*J33 -> 55 | Q33: =IF(N33="Delivered",E33-B33,"") | R33: {=_xlfn.XLOOKUP(Table1[[#This Row],[Product ID]],Table2[[#All],[Product ID]],Table2[[#All],[Category]])} -> Books | S33: {=_xlfn.XLOOKUP(Table1[[#This Row],[Customer ID]],Table4[[#All],[Customer ID]],Table4[[#All],[Customer Name]])} -> Emily Johnson | T33: =IF(E33-B33<=2,"Fast","Slow") -> Fast | U33: =IFERROR(IF(E33="","Cancellations",E33),0) -> Cancellations | V33: =IF(OR(F33<>"",N33="Cancelled"),"Cancelled","Delivered") -> Cancelled | W33: =IF(V33="Cancelled",1,0) -> 1 | X33: =VLOOKUP(H33,ProductMaster!$A$1:$E$23,2,0) -> Magazine
A34: ORD0033 | B34: 45068 | C34: =TEXT(B34,"mmm") -> May | D34: =TEXT(B34,"yyy") -> 2023 | E34: 45069 | G34: CUST016 | H34: PROD005 | I34: South | J34: 27 | K34: 2 | L34: 54 | M34: Apple Pay | N34: Delivered | O34: USPS | P34: =K34*J34 -> 54 | Q34: =IF(N34="Delivered",E34-B34,"") -> 1 | R34: {=_xlfn.XLOOKUP(Table1[[#This Row],[Product ID]],Table2[[#All],[Product ID]],Table2[[#All],[Category]])} -> Fashion | S34: {=_xlfn.XLOOKUP(Table1[[#This Row],[Customer ID]],Table4[[#All],[Customer ID]],Table4[[#All],[Customer Name]])} -> Elijah Lewis | T34: =IF(E34-B34<=2,"Fast","Slow") -> Fast | U34: =IFERROR(IF(E34="","Cancellations",E34),0) -> 45069 | V34: =IF(OR(F34<>"",N34="Cancelled"),"Cancelled","Delivered") -> Delivered | W34: =IF(V34="Cancelled",1,0) -> 0 | X34: =VLOOKUP(H34,ProductMaster!$A$1:$E$23,2,0) -> T-Shirt
A35: ORD0034 | B35: 45250 | C35: =TEXT(B35,"mmm") -> Nov | D35: =TEXT(B35,"yyy") -> 2023 | G35: CUST025 | H35: PROD015 | I35: South | J35: 21 | K35: 1 | L35: 21 | M35: Amazon Pay | N35: In Transit | O35: DHL | P35: =K35*J35 -> 21 | Q35: =IF(N35="Delivered",E35-B35,"") | R35: {=_xlfn.XLOOKUP(Table1[[#This Row],[Product ID]],Table2[[#All],[Product ID]],Table2[[#All],[Category]])} -> Books | S35: {=_xlfn.XLOOKUP(Table1[[#This Row],[Customer ID]],Table4[[#All],[Customer ID]],Table4[[#All],[Customer Name]])} -> Emma King | T35: =IF(E35-B35<=2,"Fast","Slow") -> Fast | U35: =IFERROR(IF(E35="","Cancellations",E35),0) -> Cancellations | V35: =IF(OR(F35<>"",N35="Cancelled"),"Cancelled","Delivered") -> Delivered | W35: =IF(V35="Cancelled",1,0) -> 0 | X35: =VLOOKUP(H35,ProductMaster!$A$1:$E$23,2,0) -> Novel
A36: ORD0035 | B36: 45282 | C36: =TEXT(B36,"mmm") -> Dec | D36: =TEXT(B36,"yyy") -> 2023 | E36: 45286 | G36: CUST032 | H36: PROD011 | I36: South | J36: 172 | K36: 1 | L36: 172 | M36: PayPal | N36: Delivered | O36: USPS | P36: =K36*J36 -> 172 | Q36: =IF(N36="Delivered",E36-B36,"") -> 4 | R36: {=_xlfn.XLOOKUP(Table1[[#This Row],[Product ID]],Table2[[#All],[Product ID]],Table2[[#All],[Category]])} -> Electronics | S36: {=_xlfn.XLOOKUP(Table1[[#This Row],[Customer ID]],Table4[[#All],[Customer ID]],Table4[[#All],[Customer Name]])} -> Luke Gray | T36: =IF(E36-B36<=2,"Fast","Slow") -> Slow | U36: =IFERROR(IF(E36="","Cancellations",E36),0) -> 45286 | V36: =IF(OR(F36<>"",N36="Cancelled"),"Cancelled","Delivered") -> Delivered | W36: =IF(V36="Cancelled",1,0) -> 0 | X36: =VLOOKUP(H36,ProductMaster!$A$1:$E$23,2,0) -> Headphones
A37: ORD0036 | B37: 45130 | C37: =TEXT(B37,"mmm") -> Jul | D37: =TEXT(B37,"yyy") -> 2023 | G37: CUST014 | H37: PROD016 | I37: North | J37: 212 | K37: 3 | L37: 636 | M37: Amazon Pay | N37: In Transit | O37: UPS | P37: =K37*J37 -> 636 | Q37: =IF(N37="Delivered",E37-B37,"") | R37: {=_xlfn.XLOOKUP(Table1[[#This Row],[Product ID]],Table2[[#All],[Product ID]],Table2[[#All],[Category]])} -> Home | S37: {=_xlfn.XLOOKUP(Table1[[#This Row],[Customer ID]],Table4[[#All],[Customer ID]],Table4[[#All],[Customer Name]])} -> Harper Young | T37: =IF(E37-B37<=2,"Fast","Slow") -> Fast | U37: =IFERROR(IF(E37="","Cancellations",E37),0) -> Cancellations | V37: =IF(OR(F37<>"",N37="Cancelled"),"Cancelled","Delivered") -> Delivered | W37: =IF(V37="Cancelled",1,0) -> 0 | X37: =VLOOKUP(H37,ProductMaster!$A$1:$E$23,2,0) -> Cookware Set Pro
A38: ORD0037 | B38: 45216 | C38: =TEXT(B38,"mmm") -> Oct | D38: =TEXT(B38,"yyy") -> 2023 | E38: 45221 | G38: CUST044 | H38: PROD002 | I38: East | J38: 41 | K38: 4 | L38: 164 | M38: Credit Card | N38: Delivered | O38: Amazon Logistics | P38: =K38*J38 -> 164 | Q38: =IF(N38="Delivered",E38-B38,"") -> 5 | R38: {=_xlfn.XLOOKUP(Table1[[#This Row],[Product ID]],Table2[[#All],[Product ID]],Table2[[#All],[Category]])} -> Toys | S38: {=_xlfn.XLOOKUP(Table1[[#This Row],[Customer ID]],Table4[[#All],[Customer ID]],Table4[[#All],[Customer Name]])} -> Grace Ward | T38: =IF(E38-B38<=2,"Fast","Slow") -> Slow | U38: =IFERROR(IF(E38="","Cancellations",E38),0) -> 45221 | V38: =IF(OR(F38<>"",N38="Cancelled"),"Cancelled","Delivered") -> Delivered | W38: =IF(V38="Cancelled",1,0) -> 0 | X38: =VLOOKUP(H38,ProductMaster!$A$1:$E$23,2,0) -> Action Figure
A39: ORD0038 | B39: 45160 | C39: =TEXT(B39,"mmm") -> Aug | D39: =TEXT(B39,"yyy") -> 2023 | F39: 45162 | G39: CUST028 | H39: PROD007 | I39: North | J39: 32 | K39: 2 | L39: 64 | M39: Debit Card | N39: Cancelled | O39: FedEx | P39: =K39*J39 -> 64 | Q39: =IF(N39="Delivered",E39-B39,"") | R39: {=_xlfn.XLOOKUP(Table1[[#This Row],[Product ID]],Table2[[#All],[Product ID]],Table2[[#All],[Category]])} -> Toys | S39: {=_xlfn.XLOOKUP(Table1[[#This Row],[Customer ID]],Table4[[#All],[Customer ID]],Table4[[#All],[Customer Name]])} -> Lily Bennett | T39: =IF(E39-B39<=2,"Fast","Slow") -> Fast | U39: =IFERROR(IF(E39="","Cancellations",E39),0) -> Cancellations | V39: =IF(OR(F39<>"",N39="Cancelled"),"Cancelled","Delivered") -> Cancelled | W39: =IF(V39="Cancelled",1,0) -> 1 | X39: =VLOOKUP(H39,ProductMaster!$A$1:$E$23,2,0) -> Puzzle
A40: ORD0039 | B40: 44969 | C40: =TEXT(B40,"mmm") -> Feb | D40: =TEXT(B40,"yyy") -> 2023 | G40: CUST024 | H40: PROD022 | I40: East | J40: 66 | K40: 2 | L40: 132 | M40: Apple Pay | N40: In Transit | O40: DHL | P40: =K40*J40 -> 132 | Q40: =IF(N40="Delivered",E40-B40,"") | R40: {=_xlfn.XLOOKUP(Table1[[#This Row],[Product ID]],Table2[[#All],[Product ID]],Table2[[#All],[Category]])} -> Fashion | S40: {=_xlfn.XLOOKUP(Table1[[#This Row],[Customer ID]],Table4[[#All],[Customer ID]],Table4[[#All],[Customer Name]])} -> Scarlett Murphy | T40: =IF(E40-B40<=2,"Fast","Slow") -> Fast | U40: =IFERROR(IF(E40="","Cancellations",E40),0) -> Cancellations | V40: =IF(OR(F40<>"",N40="Cancelled"),"Cancelled","Delivered") -> Delivered | W40: =IF(V40="Cancelled",1,0) -> 0 | X40: =VLOOKUP(H40,ProductMaster!$A$1:$E$23,2,0) -> Backpack
...

Sheet ProductMaster
A1: Product ID | B1: Product Name | C1: Category | D1: Cost Price | E1: Description
A2: PROD001 | B2: Smartphone | C2: Electronics | D2: 749 | E2: Latest model with 5G, dual SIM, and OLED display
A3: PROD002 | B3: Action Figure | C3: Toys | D3: 39 | E3: Collectible superhero action figure for ages 8+
A4: PROD003 | B4: Cookware Set | C4: Home | D4: 129 | E4: Non-stick 5-piece cookware set for daily use
A5: PROD004 | B5: Leg Set | C5: Toys | D5: 59 | E5: 300-piece creative building block toy set
A6: PROD005 | B6: T-Shirt | C6: Fashion | D6: 25 | E6: Cotton t-shirt, available in multiple colors
A7: PROD006 | B7: Shoes | C7: Fashion | D7: 89 | E7: Casual wear shoes for men and women
A8: PROD007 | B8: Puzzle | C8: Toys | D8: 29 | E8: 1000-piece jigsaw puzzle
A9: PROD008 | B9: Textbook | C9: Books | D9: 65 | E9: University-level textbook on computer science
A10: PROD009 | B10: Magazine | C10: Books | D10: 10 | E10: Monthly lifestyle magazine
A11: PROD010 | B11: Jeans | C11: Fashion | D11: 55 | E11: Slim fit denim jeans with stretch
A12: PROD011 | B12: Headphones | C12: Electronics | D12: 159 | E12: Wireless noise-cancelling over-ear headphones
A13: PROD012 | B13: Lamp | C13: Home | D13: 42 | E13: LED desk lamp with dimmable light
... A23: PROD022 | B23: Backpack | C23: Fashion | D23: 60 | E23: Waterproof backpack with laptop compartment

Sheet RegionGoals
A1: Region | B1: Sales Target
A2: Central | B2: 97500
A3: East | B3: 50500
A4: North | B4: 105000
A5: South | B5: 91500
A6: West | B6: 90750

Sheet CustomerMaster
A1: Customer ID | B1: Customer Name | C1: Customer Type | D1: City | E1: State
A2: CUST001 | B2: James Miller | C2: Business | D2: New York | E2: New York
A3: CUST002 | B3: Emily Johnson | C3: Prime | D3: Seattle | E3: Washington
A4: CUST003 | B4: Ethan Davis | C4: Prime | D4: Austin | E4: Texas
A5: CUST004 | B5: Noah Wilson | C5: Prime | D5: San Francisco | E5: California
A6: CUST005 | B6: Olivia Martinez | C6: Prime | D6: Seattle | E6: Washington
A7: CUST006 | B7: Ava Robinson | C7: Prime | D7: Chicago | E7: Illinois
A8: CUST007 | B8: Liam Walker | C8: Prime | D8: San Francisco | E8: California
A9: CUST008 | B9: Harper Young | C9: Business | D9: Dallas | E9: Texas
A10: CUST009 | B10: Jackson Allen | C10: Business | D10: Seattle | E10: Washington
A11: CUST010 | B11: Charlotte Harris | C11: Prime | D11: Chicago | E11: Illinois
A12: CUST011 | B12: Mason Hall | C12: Business | D12: Miami | E12: Florida
... A50: CUST049 | B50: Hazel Gray | C50: Business | D50: Chicago | E50: Illinois
